2019-11-27 09:34:44,654 ERROR: Exception on /index [GET] [in C:\Users\Samuel\projects\microblog\venv\lib\site-packages\flask\app.py:1891]
Traceback (most recent call last):
  File "C:\Users\Samuel\projects\microblog\venv\lib\site-packages\flask\app.py", line 2446, in wsgi_app
    response = self.full_dispatch_request()
  File "C:\Users\Samuel\projects\microblog\venv\lib\site-packages\flask\app.py", line 1951, in full_dispatch_request
    rv = self.handle_user_exception(e)
  File "C:\Users\Samuel\projects\microblog\venv\lib\site-packages\flask\app.py", line 1820, in handle_user_exception
    reraise(exc_type, exc_value, tb)
  File "C:\Users\Samuel\projects\microblog\venv\lib\site-packages\flask\_compat.py", line 39, in reraise
    raise value
  File "C:\Users\Samuel\projects\microblog\venv\lib\site-packages\flask\app.py", line 1949, in full_dispatch_request
    rv = self.dispatch_request()
  File "C:\Users\Samuel\projects\microblog\venv\lib\site-packages\flask\app.py", line 1935, in dispatch_request
    return self.view_functions[rule.endpoint](**req.view_args)
  File "C:\Users\Samuel\projects\microblog\venv\lib\site-packages\flask_login\utils.py", line 260, in decorated_view
    return current_app.login_manager.unauthorized()
  File "C:\Users\Samuel\projects\microblog\venv\lib\site-packages\flask_login\login_manager.py", line 175, in unauthorized
    redirect_url = make_login_url(login_view, next_url=request.url)
  File "C:\Users\Samuel\projects\microblog\venv\lib\site-packages\flask_login\utils.py", line 112, in login_url
    base = expand_login_view(login_view)
  File "C:\Users\Samuel\projects\microblog\venv\lib\site-packages\flask_login\utils.py", line 89, in expand_login_view
    return url_for(login_view)
  File "C:\Users\Samuel\projects\microblog\venv\lib\site-packages\flask\helpers.py", line 370, in url_for
    return appctx.app.handle_url_build_error(error, endpoint, values)
  File "C:\Users\Samuel\projects\microblog\venv\lib\site-packages\flask\app.py", line 2215, in handle_url_build_error
    reraise(exc_type, exc_value, tb)
  File "C:\Users\Samuel\projects\microblog\venv\lib\site-packages\flask\_compat.py", line 39, in reraise
    raise value
  File "C:\Users\Samuel\projects\microblog\venv\lib\site-packages\flask\helpers.py", line 358, in url_for
    endpoint, values, method=method, force_external=external
  File "C:\Users\Samuel\projects\microblog\venv\lib\site-packages\werkzeug\routing.py", line 2020, in build
    raise BuildError(endpoint, values, method, self)
werkzeug.routing.BuildError: Could not build url for endpoint 'login'. Did you mean 'auth.login' instead?
2019-11-27 09:35:33,886 INFO: Microblog startup [in C:\Users\Samuel\projects\microblog\app\__init__.py:56]
2019-11-27 09:36:17,076 ERROR: Exception on / [GET] [in C:\Users\Samuel\projects\microblog\venv\lib\site-packages\flask\app.py:1891]
Traceback (most recent call last):
  File "C:\Users\Samuel\projects\microblog\venv\lib\site-packages\flask\app.py", line 2446, in wsgi_app
    response = self.full_dispatch_request()
  File "C:\Users\Samuel\projects\microblog\venv\lib\site-packages\flask\app.py", line 1951, in full_dispatch_request
    rv = self.handle_user_exception(e)
  File "C:\Users\Samuel\projects\microblog\venv\lib\site-packages\flask\app.py", line 1820, in handle_user_exception
    reraise(exc_type, exc_value, tb)
  File "C:\Users\Samuel\projects\microblog\venv\lib\site-packages\flask\_compat.py", line 39, in reraise
    raise value
  File "C:\Users\Samuel\projects\microblog\venv\lib\site-packages\flask\app.py", line 1949, in full_dispatch_request
    rv = self.dispatch_request()
  File "C:\Users\Samuel\projects\microblog\venv\lib\site-packages\flask\app.py", line 1935, in dispatch_request
    return self.view_functions[rule.endpoint](**req.view_args)
  File "C:\Users\Samuel\projects\microblog\venv\lib\site-packages\flask_login\utils.py", line 260, in decorated_view
    return current_app.login_manager.unauthorized()
  File "C:\Users\Samuel\projects\microblog\venv\lib\site-packages\flask_login\login_manager.py", line 175, in unauthorized
    redirect_url = make_login_url(login_view, next_url=request.url)
  File "C:\Users\Samuel\projects\microblog\venv\lib\site-packages\flask_login\utils.py", line 112, in login_url
    base = expand_login_view(login_view)
  File "C:\Users\Samuel\projects\microblog\venv\lib\site-packages\flask_login\utils.py", line 89, in expand_login_view
    return url_for(login_view)
  File "C:\Users\Samuel\projects\microblog\venv\lib\site-packages\flask\helpers.py", line 370, in url_for
    return appctx.app.handle_url_build_error(error, endpoint, values)
  File "C:\Users\Samuel\projects\microblog\venv\lib\site-packages\flask\app.py", line 2215, in handle_url_build_error
    reraise(exc_type, exc_value, tb)
  File "C:\Users\Samuel\projects\microblog\venv\lib\site-packages\flask\_compat.py", line 39, in reraise
    raise value
  File "C:\Users\Samuel\projects\microblog\venv\lib\site-packages\flask\helpers.py", line 358, in url_for
    endpoint, values, method=method, force_external=external
  File "C:\Users\Samuel\projects\microblog\venv\lib\site-packages\werkzeug\routing.py", line 2020, in build
    raise BuildError(endpoint, values, method, self)
werkzeug.routing.BuildError: Could not build url for endpoint 'login'. Did you mean 'auth.login' instead?
2019-11-27 09:55:42,309 INFO: Microblog startup [in C:\Users\Samuel\projects\microblog\app\__init__.py:56]
2019-11-27 09:55:48,100 ERROR: Exception on / [GET] [in C:\Users\Samuel\projects\microblog\venv\lib\site-packages\flask\app.py:1891]
Traceback (most recent call last):
  File "C:\Users\Samuel\projects\microblog\venv\lib\site-packages\flask\app.py", line 2446, in wsgi_app
    response = self.full_dispatch_request()
  File "C:\Users\Samuel\projects\microblog\venv\lib\site-packages\flask\app.py", line 1951, in full_dispatch_request
    rv = self.handle_user_exception(e)
  File "C:\Users\Samuel\projects\microblog\venv\lib\site-packages\flask\app.py", line 1820, in handle_user_exception
    reraise(exc_type, exc_value, tb)
  File "C:\Users\Samuel\projects\microblog\venv\lib\site-packages\flask\_compat.py", line 39, in reraise
    raise value
  File "C:\Users\Samuel\projects\microblog\venv\lib\site-packages\flask\app.py", line 1949, in full_dispatch_request
    rv = self.dispatch_request()
  File "C:\Users\Samuel\projects\microblog\venv\lib\site-packages\flask\app.py", line 1935, in dispatch_request
    return self.view_functions[rule.endpoint](**req.view_args)
  File "C:\Users\Samuel\projects\microblog\venv\lib\site-packages\flask_login\utils.py", line 260, in decorated_view
    return current_app.login_manager.unauthorized()
  File "C:\Users\Samuel\projects\microblog\venv\lib\site-packages\flask_login\login_manager.py", line 175, in unauthorized
    redirect_url = make_login_url(login_view, next_url=request.url)
  File "C:\Users\Samuel\projects\microblog\venv\lib\site-packages\flask_login\utils.py", line 112, in login_url
    base = expand_login_view(login_view)
  File "C:\Users\Samuel\projects\microblog\venv\lib\site-packages\flask_login\utils.py", line 89, in expand_login_view
    return url_for(login_view)
  File "C:\Users\Samuel\projects\microblog\venv\lib\site-packages\flask\helpers.py", line 370, in url_for
    return appctx.app.handle_url_build_error(error, endpoint, values)
  File "C:\Users\Samuel\projects\microblog\venv\lib\site-packages\flask\app.py", line 2215, in handle_url_build_error
    reraise(exc_type, exc_value, tb)
  File "C:\Users\Samuel\projects\microblog\venv\lib\site-packages\flask\_compat.py", line 39, in reraise
    raise value
  File "C:\Users\Samuel\projects\microblog\venv\lib\site-packages\flask\helpers.py", line 358, in url_for
    endpoint, values, method=method, force_external=external
  File "C:\Users\Samuel\projects\microblog\venv\lib\site-packages\werkzeug\routing.py", line 2020, in build
    raise BuildError(endpoint, values, method, self)
werkzeug.routing.BuildError: Could not build url for endpoint 'login'. Did you mean 'auth.login' instead?
2019-11-27 09:57:27,634 INFO: Microblog startup [in C:\Users\Samuel\projects\microblog\app\__init__.py:56]
